Workbook

Sheet Test Summary
B1: DATALOGGER ANALYSIS APPLICATION — QUALITY ASSURANCE TEST REPORT
B2: Document ID: DAA-QA-001 | Version: 1.0 | Status: Draft for QA Execution | Project: Datalogger Analysis Application (Edge Local)
B4: Prepared By | C4: PT. Cipta Bina Instrumentasi (QA Team) | G4: Test Execution Date | H4: 2026-10-23 s/d 2026-10-30
B5: Project / Site | C5: AQMS Monitoring Station (Edge SCADA) | G5: QA Lead Engineer | H5: [Nama QA Engineer]
B6: Tested Version | C6: Release v2.7.0-RC1 (Commit: 7327a79) | G6: System Analyst | H6: [Nama System Analyst]
B7: Target Platform | C7: Industrial Linux ARM64 / Win10 x64 | G7: Lead Instrumentation | H7: [Nama Lead Instrumentation]
B8: Test Environment | C8: Staging Hardware Testbed (Modbus RTU & TCP) | G8: Approval Authority | H8: [Nama Project Manager / Commissioning Lead]
B10: TOTAL TEST CASES | D10: NOT TESTED | E10: PASSED | F10: FAILED | G10: BLOCKED | H10: EXECUTION % | J10: PASS RATE %
B11: =C30 | D11: =D30 | E11: =E30 | F11: =F30 | G11: =G30 | H11: =IF(C30>0,(E30+F30+G30+H30)/C30,0) | J11: =IF((E30+F30)>0,E30/(E30+F30),0)
B14: QA TEST EXECUTION BREAKDOWN BY MODULE
B15: Test Category / Scope Module | C15: Total Cases | D15: Not Tested | E15: Passed | F15: Failed | G15: Blocked | H15: N/A | I15: Execution % | J15: Pass Rate % | K15: Status / Readiness
B16: Installation & Deployment | C16: =COUNTA('Installation & Deployment'!A5:A16) | D16: =COUNTIF('Installation & Deployment'!H5:H16, "NOT TESTED") | E16: =COUNTIF('Installation & Deployment'!H5:H16, "PASS") | F16: =COUNTIF('Installation & Deployment'!H5:H16, "FAIL") | G16: =COUNTIF('Installation & Deployment'!H5:H16, "BLOCKED") | H16: =COUNTIF('Installation & Deployment'!H5:H16, "NOT APPLICABLE") | I16: =IF(C16>0, (C16-D16)/C16, 0) | J16: =IF((E16+F16)>0, E16/(E16+F16), 0) | K16: =IF(D16=C16, "NOT STARTED", IF(F16>0, "DEFECTS OPEN", IF(E16=C16, "PASSED ALL", "TESTING")))
B17: Authentication & Authorization | C17: =COUNTA('Authentication & Authorization'!A5:A16) | D17: =COUNTIF('Authentication & Authorization'!H5:H16, "NOT TESTED") | E17: =COUNTIF('Authentication & Authorization'!H5:H16, "PASS") | F17: =COUNTIF('Authentication & Authorization'!H5:H16, "FAIL") | G17: =COUNTIF('Authentication & Authorization'!H5:H16, "BLOCKED") | H17: =COUNTIF('Authentication & Authorization'!H5:H16, "NOT APPLICABLE") | I17: =IF(C17>0, (C17-D17)/C17, 0) | J17: =IF((E17+F17)>0, E17/(E17+F17), 0) | K17: =IF(D17=C17, "NOT STARTED", IF(F17>0, "DEFECTS OPEN", IF(E17=C17, "PASSED ALL", "TESTING")))
B18: Device & Communication | C18: =COUNTA('Device & Communication'!A5:A18) | D18: =COUNTIF('Device & Communication'!H5:H18, "NOT TESTED") | E18: =COUNTIF('Device & Communication'!H5:H18, "PASS") | F18: =COUNTIF('Device & Communication'!H5:H18, "FAIL") | G18: =COUNTIF('Device & Communication'!H5:H18, "BLOCKED") | H18: =COUNTIF('Device & Communication'!H5:H18, "NOT APPLICABLE") | I18: =IF(C18>0, (C18-D18)/C18, 0) | J18: =IF((E18+F18)>0, E18/(E18+F18), 0) | K18: =IF(D18=C18, "NOT STARTED", IF(F18>0, "DEFECTS OPEN", IF(E18=C18, "PASSED ALL", "TESTING")))
B19: Parameter & Decoding | C19: =COUNTA('Parameter & Decoding'!A5:A18) | D19: =COUNTIF('Parameter & Decoding'!H5:H18, "NOT TESTED") | E19: =COUNTIF('Parameter & Decoding'!H5:H18, "PASS") | F19: =COUNTIF('Parameter & Decoding'!H5:H18, "FAIL") | G19: =COUNTIF('Parameter & Decoding'!H5:H18, "BLOCKED") | H19: =COUNTIF('Parameter & Decoding'!H5:H18, "NOT APPLICABLE") | I19: =IF(C19>0, (C19-D19)/C19, 0) | J19: =IF((E19+F19)>0, E19/(E19+F19), 0) | K19: =IF(D19=C19, "NOT STARTED", IF(F19>0, "DEFECTS OPEN", IF(E19=C19, "PASSED ALL", "TESTING")))
B20: Polling Plan & Batch Read | C20: =COUNTA('Polling Plan & Batch Read'!A5:A18) | D20: =COUNTIF('Polling Plan & Batch Read'!H5:H18, "NOT TESTED") | E20: =COUNTIF('Polling Plan & Batch Read'!H5:H18, "PASS") | F20: =COUNTIF('Polling Plan & Batch Read'!H5:H18, "FAIL") | G20: =COUNTIF('Polling Plan & Batch Read'!H5:H18, "BLOCKED") | H20: =COUNTIF('Polling Plan & Batch Read'!H5:H18, "NOT APPLICABLE") | I20: =IF(C20>0, (C20-D20)/C20, 0) | J20: =IF((E20+F20)>0, E20/(E20+F20), 0) | K20: =IF(D20=C20, "NOT STARTED", IF(F20>0, "DEFECTS OPEN", IF(E20=C20, "PASSED ALL", "TESTING")))
B21: Telemetry & Data Integrity | C21: =COUNTA('Telemetry & Data Integrity'!A5:A16) | D21: =COUNTIF('Telemetry & Data Integrity'!H5:H16, "NOT TESTED") | E21: =COUNTIF('Telemetry & Data Integrity'!H5:H16, "PASS") | F21: =COUNTIF('Telemetry & Data Integrity'!H5:H16, "FAIL") | G21: =COUNTIF('Telemetry & Data Integrity'!H5:H16, "BLOCKED") | H21: =COUNTIF('Telemetry & Data Integrity'!H5:H16, "NOT APPLICABLE") | I21: =IF(C21>0, (C21-D21)/C21, 0) | J21: =IF((E21+F21)>0, E21/(E21+F21), 0) | K21: =IF(D21=C21, "NOT STARTED", IF(F21>0, "DEFECTS OPEN", IF(E21=C21, "PASSED ALL", "TESTING")))
B22: Aggregation & Rollup | C22: =COUNTA('Aggregation & Rollup'!A5:A14) | D22: =COUNTIF('Aggregation & Rollup'!H5:H14, "NOT TESTED") | E22: =COUNTIF('Aggregation & Rollup'!H5:H14, "PASS") | F22: =COUNTIF('Aggregation & Rollup'!H5:H14, "FAIL") | G22: =COUNTIF('Aggregation & Rollup'!H5:H14, "BLOCKED") | H22: =COUNTIF('Aggregation & Rollup'!H5:H14, "NOT APPLICABLE") | I22: =IF(C22>0, (C22-D22)/C22, 0) | J22: =IF((E22+F22)>0, E22/(E22+F22), 0) | K22: =IF(D22=C22, "NOT STARTED", IF(F22>0, "DEFECTS OPEN", IF(E22=C22, "PASSED ALL", "TESTING")))
B23: Dashboard & UI | C23: =COUNTA('Dashboard & UI'!A5:A20) | D23: =COUNTIF('Dashboard & UI'!H5:H20, "NOT TESTED") | E23: =COUNTIF('Dashboard & UI'!H5:H20, "PASS") | F23: =COUNTIF('Dashboard & UI'!H5:H20, "FAIL") | G23: =COUNTIF('Dashboard & UI'!H5:H20, "BLOCKED") | H23: =COUNTIF('Dashboard & UI'!H5:H20, "NOT APPLICABLE") | I23: =IF(C23>0, (C23-D23)/C23, 0) | J23: =IF((E23+F23)>0, E23/(E23+F23), 0) | K23: =IF(D23=C23, "NOT STARTED", IF(F23>0, "DEFECTS OPEN", IF(E23=C23, "PASSED ALL", "TESTING")))
B24: Historical Data & Export | C24: =COUNTA('Historical Data & Export'!A5:A16) | D24: =COUNTIF('Historical Data & Export'!H5:H16, "NOT TESTED") | E24: =COUNTIF('Historical Data & Export'!H5:H16, "PASS") | F24: =COUNTIF('Historical Data & Export'!H5:H16, "FAIL") | G24: =COUNTIF('Historical Data & Export'!H5:H16, "BLOCKED") | H24: =COUNTIF('Historical Data & Export'!H5:H16, "NOT APPLICABLE") | I24: =IF(C24>0, (C24-D24)/C24, 0) | J24: =IF((E24+F24)>0, E24/(E24+F24), 0) | K24: =IF(D24=C24, "NOT STARTED", IF(F24>0, "DEFECTS OPEN", IF(E24=C24, "PASSED ALL", "TESTING")))
B25: Alarm, Logs & Audit Trail | C25: =COUNTA('Alarm, Logs & Audit Trail'!A5:A16) | D25: =COUNTIF('Alarm, Logs & Audit Trail'!H5:H16, "NOT TESTED") | E25: =COUNTIF('Alarm, Logs & Audit Trail'!H5:H16, "PASS") | F25: =COUNTIF('Alarm, Logs & Audit Trail'!H5:H16, "FAIL") | G25: =COUNTIF('Alarm, Logs & Audit Trail'!H5:H16, "BLOCKED") | H25: =COUNTIF('Alarm, Logs & Audit Trail'!H5:H16, "NOT APPLICABLE") | I25: =IF(C25>0, (C25-D25)/C25, 0) | J25: =IF((E25+F25)>0, E25/(E25+F25), 0) | K25: =IF(D25=C25, "NOT STARTED", IF(F25>0, "DEFECTS OPEN", IF(E25=C25, "PASSED ALL", "TESTING")))
B26: Backup, Restore & Retention | C26: =COUNTA('Backup, Restore & Retention'!A5:A14) | D26: =COUNTIF('Backup, Restore & Retention'!H5:H14, "NOT TESTED") | E26: =COUNTIF('Backup, Restore & Retention'!H5:H14, "PASS") | F26: =COUNTIF('Backup, Restore & Retention'!H5:H14, "FAIL") | G26: =COUNTIF('Backup, Restore & Retention'!H5:H14, "BLOCKED") | H26: =COUNTIF('Backup, Restore & Retention'!H5:H14, "NOT APPLICABLE") | I26: =IF(C26>0, (C26-D26)/C26, 0) | J26: =IF((E26+F26)>0, E26/(E26+F26), 0) | K26: =IF(D26=C26, "NOT STARTED", IF(F26>0, "DEFECTS OPEN", IF(E26=C26, "PASSED ALL", "TESTING")))
B27: Performance & Security | C27: =COUNTA('Performance & Security'!A5:A16) | D27: =COUNTIF('Performance & Security'!H5:H16, "NOT TESTED") | E27: =COUNTIF('Performance & Security'!H5:H16, "PASS") | F27: =COUNTIF('Performance & Security'!H5:H16, "FAIL") | G27: =COUNTIF('Performance & Security'!H5:H16, "BLOCKED") | H27: =COUNTIF('Performance & Security'!H5:H16, "NOT APPLICABLE") | I27: =IF(C27>0, (C27-D27)/C27, 0) | J27: =IF((E27+F27)>0, E27/(E27+F27), 0) | K27: =IF(D27=C27, "NOT STARTED", IF(F27>0, "DEFECTS OPEN", IF(E27=C27, "PASSED ALL", "TESTING")))
B28: Customer Acceptance | C28: =COUNTA('Customer Acceptance'!A5:A16) | D28: =COUNTIF('Customer Acceptance'!H5:H16, "NOT TESTED") | E28: =COUNTIF('Customer Acceptance'!H5:H16, "PASS") | F28: =COUNTIF('Customer Acceptance'!H5:H16, "FAIL") | G28: =COUNTIF('Customer Acceptance'!H5:H16, "BLOCKED") | H28: =COUNTIF('Customer Acceptance'!H5:H16, "NOT APPLICABLE") | I28: =IF(C28>0, (C28-D28)/C28, 0) | J28: =IF((E28+F28)>0, E28/(E28+F28), 0) | K28: =IF(D28=C28, "NOT STARTED", IF(F28>0, "DEFECTS OPEN", IF(E28=C28, "PASSED ALL", "TESTING")))
B30: TOTAL / OVERALL PROJECT PROGRESS | C30: =SUM(C16:C28) | D30: =SUM(D16:D28) | E30: =SUM(E16:E28) | F30: =SUM(F16:F28) | G30: =SUM(G16:G28) | H30: =SUM(H16:H28) | I30: =IF(C30>0, (C30-D30)/C30, 0) | J30: =IF((E30+F30)>0, E30/(E30+F30), 0) | K30: =IF(D30=C30, "READY FOR QA EXECUTION", IF(F30>0, "DEFECTS OPEN", IF(E30=C30, "ALL PASSED", "TESTING IN PROGRESS")))
B32: DEFECT SUMMARY BY SEVERITY | G32: RELEASE GATE CRITERIA & COMMISSIONING READINESS
B33: Severity Level | C33: Total Logged | D33: Release Gate Threshold | G33: Gate 1: 100% Critical & High test cases executed without blocker | J33: PENDING EXECUTION
B34: Critical | C34: =COUNTIF('Defect Log'!E5:E35, "Critical") | D34: 0 Allowed (Strict Blocker) | G34: Gate 2: 0 Open Critical & 0 Open High Defects in Defect Log | J34: PENDING EXECUTION
B35: High | C35: =COUNTIF('Defect Log'!E5:E35, "High") | D35: 0 Allowed (Must be Resolved) | G35: Gate 3: Hardware testbed validation on actual Modbus RTU/TCP passed | J35: PENDING HARDWARE
B36: Medium | C36: =COUNTIF('Defect Log'!E5:E35, "Medium") | D36: Max 3 (With Agreed Workaround) | G36: Gate 4: 24h Stability & Memory Leak test under 5s polling cadence passed | J36: PENDING SOAK TEST
B37: Low | C37: =COUNTIF('Defect Log'!E5:E35, "Low") | D37: Tolerable for Handover | G37: Gate 5: Customer User Manual (DAA-CUM-001) verified and handed over | J37: READY (DOCX AVAILABLE)
B40: OFFICIAL COMMISSIONING & RELEASE SIGN-OFF
B41: Role / Responsibility | E41: Full Name | G41: Signature & Stamp | I41: Date | J41: Approval Status
B42: QA Lead Engineer | E42: [Nama QA Lead] | G42: [ Sign Here ] | I42: YYYY-MM-DD | J42: PENDING AUDIT
B43: Lead Instrumentation Engineer | E43: [Nama Lead Instrumentation] | G43: [ Sign Here ] | I43: YYYY-MM-DD | J43: PENDING WITNESS
B44: System Analyst / Architect | E44: [Nama System Analyst] | G44: [ Sign Here ] | I44: YYYY-MM-DD | J44: PENDING REVIEW
B45: Project Manager / Commissioning Lead | E45: [Nama Project Manager] | G45: [ Sign Here ] | I45: YYYY-MM-DD | J45: PENDING RELEASE

Sheet Installation & Deployment
A1: DATALOGGER ANALYSIS APPLICATION — QA TEST CHECKLIST
A2: Module: Installation & Deployment | Doc ID: DAA-QA-001 | Version: 1.0 | Status: Draft for QA Execution | Scope: Pengujian prasyarat server, build artifact, database migration, dan daemon lifecycle.
A4: Test Case ID | B4: Test Category | C4: Test Scenario | D4: Preconditions | E4: Test Steps | F4: Expected Result | G4: Actual Result | H4: Status | I4: Severity | J4: Evidence Reference | K4: Defect ID | L4: Tester | M4: Test Date | N4: Remarks
A5: TC-INST-001 | B5: Installation | C5: Verifikasi prasyarat sistem operasi dan dependensi runtime | D5: Server target (Linux ARM64 / Windows 10/11) tersedia dengan Go 1.20+, Node.js 18+, MariaDB 10.4+ | E5: 1. Jalankan 'go version' dan 'node -v' 2. Periksa ketersediaan paket libpcap dan driver serial 3. Verifikasi alokasi memori RAM minimal 2GB | F5: Semua dependensi terpasang sesuai spesifikasi arsitektur target tanpa error | H5: NOT TESTED | I5: High | J5: REQ-SYS-01 | L5: [Tester] | M5: [Date]
A6: TC-INST-002 | B6: Installation | C6: Kompilasi backend Go binary secara bersih | D6: Repository bersih pada branch release | E6: 1. Jalankan 'go build -o datalogger ./cmd/main.go' 2. Periksa exit code kompilasi 3. Verifikasi ukuran binary executable | F6: Binary berhasil terkompilasi dengan exit code 0 tanpa error linking atau compiler warning | H6: NOT TESTED | I6: Critical | J6: REQ-SYS-02 | L6: [Tester] | M6: [Date]
A7: TC-INST-003 | B7: Installation | C7: Kompilasi bundle frontend Vue 2 + Vite | D7: Direktori web memiliki node_modules terpasang | E7: 1. Masuk ke direktori web 2. Jalankan 'npm run build' 3. Periksa direktori web/dist | F7: Vite menghasilkan aset produksi web/dist/index.html dan bundle JS/CSS teroptimasi | H7: NOT TESTED | I7: Critical | J7: REQ-SYS-03 | L7: [Tester] | M7: [Date]
A8: TC-INST-004 | B8: Installation | C8: Konektivitas MariaDB Edge Local storage | D8: Service MariaDB berjalan pada 127.0.0.1:3306 | E8: 1. Periksa koneksi TCP port 3306 2. Lakukan login menggunakan kredensial datalogger 3. Jalankan query SELECT 1 | F8: Koneksi database lokal berhasil dengan latensi di bawah 10ms | H8: NOT TESTED | I8: Critical | J8: REQ-DB-01 | L8: [Tester] | M8: [Date]
A9: TC-INST-005 | B9: Installation | C9: Eksekusi otomatis migrasi skema database | D9: Database datalogger belum memiliki tabel terbaru | E9: 1. Jalankan aplikasi pertama kali 2. Periksa log startup migration 3. Periksa tabel devices, parameters, telemetry_readings | F9: Seluruh tabel schema Phase 1 s/d Phase 10 terbuat otomatis secara idempotensial | H9: NOT TESTED | I9: Critical | J9: REQ-DB-02 | L9: [Tester] | M9: [Date]
A10: TC-INST-006 | B10: Installation | C10: Validasi konfigurasi config.json dan environment | D10: File config.json tersedia di direktori kerja | E10: 1. Buka config.json 2. Verifikasi host, port, db_name, serial port defaults 3. Uji penimpaan via environment variable | F10: Konfigurasi dimuat dengan benar dan fallback default aktif jika field kosong | H10: NOT TESTED | I10: High | J10: REQ-CFG-01 | L10: [Tester] | M10: [Date]
A11: TC-INST-007 | B11: Installation | C11: Lifecycle service: Start dan Stop graceful shutdown | D11: Aplikasi sedang berjalan normal | E11: 1. Jalankan service daemon 2. Kirim sinyal SIGINT / SIGTERM 3. Amati log penutupan pool database dan worker polling | F11: Aplikasi berhenti secara anggun (graceful) tanpa data korup dalam waktu < 5 detik | H11: NOT TESTED | I11: High | J11: REQ-SYS-04 | L11: [Tester] | M11: [Date]
A12: TC-INST-008 | B12: Installation | C12: Auto-start service setelah system reboot | D12: Systemd service / Task scheduler terkonfigurasi | E12: 1. Lakukan reboot pada host server 2. Tunggu hingga OS selesai booting 3. Periksa status service 'systemctl status datalogger' | F12: Service datalogger otomatis berjalan kembali dan langsung memulai polling tanpa intervensi manual | H12: NOT TESTED | I12: Critical | J12: REQ-SYS-05 | L12: [Tester] | M12: [Date]
A13: TC-INST-009 | B13: Installation | C13: Binding HTTP port 8080 dan reverse proxy | D13: Service datalogger aktif | E13: 1. Jalankan 'curl -I http://localhost:8080/api/system/health' 2. Periksa respons header | F13: Endpoint HTTP 8080 merespons dengan status 200 OK dan header CORS terkonfigurasi | H13: NOT TESTED | I13: High | J13: REQ-NET-01 | L13: [Tester] | M13: [Date]
A14: TC-INST-010 | B14: Installation | C14: Aksesibilitas antarmuka web melalui browser | D14: Workstation klien terhubung ke jaringan stasiun | E14: 1. Buka Google Chrome 2. Akses http://[IP_Server]:8080 3. Verifikasi halaman dimuat | F14: Aplikasi web Single Page Application berhasil dimuat dalam waktu < 2 detik | H14: NOT TESTED | I14: High | J14: REQ-UI-01 | L14: [Tester] | M14: [Date]
A15: TC-INST-011 | B15: Installation | C15: Audit ketiadaan rahasia (secrets) pada client bundle | D15: Aset web/dist telah terkompilasi | E15: 1. Lakukan grep pada bundle JS untuk kata kunci 'Password123!', db password, atau private keys | F15: Tidak ada kredensial database atau secret server yang terekspos pada sisi klien | H15: NOT TESTED | I15: Critical | J15: REQ-SEC-01 | L15: [Tester] | M15: [Date]
A16: TC-INST-012 | B16: Installation | C16: Rotasi dan penulisan file log startup | D16: Direktori logs/ terkonfigurasi | E16: 1. Periksa file logs/datalogger.log 2. Verifikasi format timestamp, level [INFO], dan jejak subsystem | F16: Log tercatat rapi dengan level logging terstruktur tanpa membanjiri disk | H16: NOT TESTED | I16: Medium | J16: REQ-LOG-01 | L16: [Tester] | M16: [Date]

Sheet Authentication & Authorization
A1: DATALOGGER ANALYSIS APPLICATION — QA TEST CHECKLIST
A2: Module: Authentication & Authorization | Doc ID: DAA-QA-001 | Version: 1.0 | Status: Draft for QA Execution | Scope: Pengujian autentikasi JWT, password hashing bcrypt, kontrol peran (RBAC), dan proteksi endpoint.
A4: Test Case ID | B4: Test Category | C4: Test Scenario | D4: Preconditions | E4: Test Steps | F4: Expected Result | G4: Actual Result | H4: Status | I4: Severity | J4: Evidence Reference | K4: Defect ID | L4: Tester | M4: Test Date | N4: Remarks
A5: TC-AUTH-001 | B5: Authentication | C5: Login menggunakan akun valid (Operator, Engineer, Admin, Superadmin) | D5: Pengguna memiliki akun terdaftar di database | E5: 1. Buka /#/login 2. Masukkan username 'operator_user' dan password valid 3. Klik 'Sign In →' | F5: Login sukses, JWT token tersimpan di client, diarahkan langsung ke Operator Console | H5: NOT TESTED | I5: Critical | J5: REQ-AUTH-01 | L5: [Tester] | M5: [Date]
A6: TC-AUTH-002 | B6: Authentication | C6: Login dengan password salah menampilkan pesan error | D6: Halaman /#/login terbuka | E6: 1. Masukkan username valid 2. Masukkan password salah 3. Klik 'Sign In →' | F6: Login ditolak, sistem menampilkan toast merah 'Invalid username or password' tanpa membocorkan detail akun | H6: NOT TESTED | I6: High | J6: REQ-AUTH-02 | L6: [Tester] | M6: [Date]
A7: TC-AUTH-003 | B7: Authentication | C7: Validasi form login terhadap input kosong | D7: Halaman /#/login terbuka | E7: 1. Kosongkan username atau password 2. Klik 'Sign In →' | F7: Validasi form HTML5/Vue aktif mencegah submit data kosong | H7: NOT TESTED | I7: Medium | J7: REQ-AUTH-03 | L7: [Tester] | M7: [Date]
A8: TC-AUTH-004 | B8: Authentication | C8: Prosedur logout dan pembersihan token sesi | D8: Pengguna sedang login di aplikasi | E8: 1. Klik badge akun di Header 2. Pilih Logout 3. Konfirmasi pada modal 'Confirm Session Logout' | F8: Token dibersihkan dari localStorage, sesi berakhir, diarahkan kembali ke /#/login | H8: NOT TESTED | I8: High | J8: REQ-AUTH-04 | L8: [Tester] | M8: [Date]
A9: TC-AUTH-005 | B9: Authentication | C9: Penanganan sesi kedaluwarsa (Expired JWT) | D9: Token JWT diubah secara manual menjadi expired | E9: 1. Lakukan request API dengan expired token 2. Amati respons backend dan aksi frontend | F9: Backend mengembalikan HTTP 401 Unauthorized, frontend otomatis mengarahkan ke login | H9: NOT TESTED | I9: High | J9: REQ-AUTH-05 | L9: [Tester] | M9: [Date]
A10: TC-AUTH-006 | B10: Authentication | C10: Proteksi rute tanpa autentikasi (Unauthenticated Redirect) | D10: Browser dalam status unauthenticated (tanpa token) | E10: 1. Akses langsung URL /#/monitoring/devices atau /#/alarm/active via address bar | F10: Route guard Vue Router mencegat navigasi dan me-redirect ke /#/login?redirect=... | H10: NOT TESTED | I10: Critical | J10: REQ-AUTH-06 | L10: [Tester] | M10: [Date]
A11: TC-AUTH-007 | B11: RBAC | C11: Pembatasan hak akses role OPERATOR | D11: Login sebagai @operator_user (Role OPERATOR) | E11: 1. Coba akses menu /#/administration/config atau /#/administration/users via URL | F11: Navigasi dicegat, sistem menampilkan layar proteksi 'Access Restricted (HTTP 403)' | H11: NOT TESTED | I11: Critical | J11: REQ-RBAC-01 | L11: [Tester] | M11: [Date]
A12: TC-AUTH-008 | B12: RBAC | C12: Kewenangan role ENGINEER untuk konfigurasi perangkat | D12: Login sebagai @engineer_user (Role ENGINEER) | E12: 1. Buka /#/monitoring/devices 2. Buka modal edit perangkat dan parameter | F12: Engineer berwenang mengubah baud rate, formula, dan melakukan Test Read register | H12: NOT TESTED | I12: High | J12: REQ-RBAC-02 | L12: [Tester] | M12: [Date]
A13: TC-AUTH-009 | B13: RBAC | C13: Kewenangan role ADMIN untuk manajemen user customer | D13: Login sebagai @admin_user (Role ADMIN) | E13: 1. Buka /#/administration/users 2. Tambah user baru bertipe OPERATOR | F13: Admin dapat membuat, mengedit, dan menonaktifkan akun operator lokal | H13: NOT TESTED | I13: High | J13: REQ-RBAC-03 | L13: [Tester] | M13: [Date]
A14: TC-AUTH-010 | B14: RBAC | C14: Eksklusivitas role SUPERADMIN untuk development tracking | D14: Login sebagai @admin (Role SUPERADMIN) | E14: 1. Periksa sidebar menu 2. Buka /#/development dan /#/dashboard | F14: Menu Development Phases, Tasks, dan Quality hanya muncul dan dapat diakses oleh SUPERADMIN | H14: NOT TESTED | I14: Critical | J14: REQ-RBAC-04 | L14: [Tester] | M14: [Date]
A15: TC-AUTH-011 | B15: Security | C15: Validasi Authorization header Bearer pada API endpoints | D15: Tools pengujian API (cURL / Postman) | E15: 1. Request GET /api/devices tanpa header Authorization 2. Request dengan header 'Bearer invalid_token' | F15: Backend menolak dengan HTTP 401 Unauthorized dan format JSON error baku | H15: NOT TESTED | I15: Critical | J15: REQ-API-01 | L15: [Tester] | M15: [Date]
A16: TC-AUTH-012 | B16: Security | C16: Audit keamanan log kredensial (Credential Log Hygiene) | D16: Pengguna melakukan login dan registrasi user | E16: 1. Periksa file logs/datalogger.log 2. Cari string password yang baru dikirim | F16: Password dalam payload tidak pernah dicatat dalam plain text pada log server | H16: NOT TESTED | I16: Critical | J16: REQ-SEC-02 | L16: [Tester] | M16: [Date]

Sheet Device & Communication
A1: DATALOGGER ANALYSIS APPLICATION — QA TEST CHECKLIST
A2: Module: Device & Communication | Doc ID: DAA-QA-001 | Version: 1.0 | Status: Draft for QA Execution | Scope: Pengujian pendaftaran perangkat fisik, konfigurasi serial/TCP Modbus, timeout, dan auto-reconnect.
A4: Test Case ID | B4: Test Category | C4: Test Scenario | D4: Preconditions | E4: Test Steps | F4: Expected Result | G4: Actual Result | H4: Status | I4: Severity | J4: Evidence Reference | K4: Defect ID | L4: Tester | M4: Test Date | N4: Remarks
A5: TC-DEV-001 | B5: Device Setup | C5: Pendaftaran perangkat Modbus RTU baru (AQMS-01) | D5: Login sebagai Admin/Engineer pada menu Devices | E5: 1. Klik tombol '+ Register Device' 2. Masukkan kode 'AQMS-01', tipe MODBUS_RTU, serial port '/dev/ttyUSB0', baud 9600, slave ID 1 3. Simpan | F5: Perangkat tersimpan di database dan muncul pada tabel daftar perangkat | H5: NOT TESTED | I5: Critical | J5: REQ-DEV-01 | L5: [Tester] | M5: [Date]
A6: TC-DEV-002 | B6: Device Setup | C6: Pendaftaran perangkat Modbus TCP baru dengan IP Host dan Port | D6: Tersedia gateway Modbus TCP | E6: 1. Daftarkan perangkat dengan tipe MODBUS_TCP, host '192.168.1.20', port 502, slave ID 1 2. Simpan | F6: Koneksi TCP terkonfigurasi dengan benar tanpa error validasi | H6: NOT TESTED | I6: High | J6: REQ-DEV-02 | L6: [Tester] | M6: [Date]
A7: TC-DEV-003 | B7: Device Setup | C7: Pengeditan parameter konfigurasi perangkat terdaftar | D7: Perangkat AQMS-01 telah terdaftar | E7: 1. Klik ikon Edit pada baris perangkat 2. Ubah polling interval dari 5000ms menjadi 3000ms 3. Simpan perubahan | F7: Perubahan tersimpan dan engine menerapkan interval polling baru tanpa restart | H7: NOT TESTED | I7: High | J7: REQ-DEV-03 | L7: [Tester] | M7: [Date]
A8: TC-DEV-004 | B8: Device Setup | C8: Validasi integritas field wajib dan keunikan device_code | D8: Modal tambah perangkat terbuka | E8: 1. Coba simpan perangkat dengan device_code yang sudah ada 2. Coba simpan tanpa mengisi nama perangkat | F8: Sistem menolak dan menampilkan pesan validasi spesifik | H8: NOT TESTED | I8: Medium | J8: REQ-DEV-04 | L8: [Tester] | M8: [Date]
A9: TC-DEV-005 | B9: Modbus Serial | C9: Konfigurasi serial port, baud rate, parity, dan stop bits | D9: Perangkat terhubung via RS-485 | E9: 1. Atur port baud 9600, data bits 8, parity None (N), stop bits 1 2. Jalankan Test Read | F9: Driver serial membuka port dengan parameter framing UART yang sesuai | H9: NOT TESTED | I9: Critical | J9: REQ-COMM-01 | L9: [Tester] | M9: [Date]
A10: TC-DEV-006 | B10: Modbus Addressing | C10: Validasi Slave ID valid (1 - 247) dan penolakan Slave ID invalid | D10: Modal konfigurasi perangkat | E10: 1. Masukkan slave ID 0 atau 255 2. Masukkan slave ID 6 | F10: Sistem membatasi input slave ID hanya pada rentang standar Modbus 1 - 247 | H10: NOT TESTED | I10: Medium | J10: REQ-COMM-02 | L10: [Tester] | M10: [Date]
A11: TC-DEV-007 | B11: Modbus Timing | C11: Uji timeout komunikasi dan retry policy | D11: Kabel sensor sengaja dilepas sementara | E11: 1. Atur timeout 2000ms, retry count 3 2. Lakukan polling 3. Amati log waktu tunggu | F11: Engine mencoba ulang tepat 3 kali sebelum menandai request gagal setelah 6000ms total | H11: NOT TESTED | I11: High | J11: REQ-COMM-03 | L11: [Tester] | M11: [Date]
A12: TC-DEV-008 | B12: Diagnostics | C12: Fungsi uji pembacaan register (Test Read) pada UI | D12: Perangkat sensor online terhubung | E12: 1. Buka modal Test Read pada perangkat AQMS-01 2. Pilih register holding address 0, count 2 3. Klik 'Execute Test Read' | F12: Modal menampilkan respons raw hex dan nilai hasil konversi secara instan | H12: NOT TESTED | I12: High | J12: REQ-DEV-05 | L12: [Tester] | M12: [Date]
A13: TC-DEV-009 | B13: Status Integrity | C13: Konsistensi status ONLINE saat polling Modbus sukses | D13: Sensor merespons polling secara normal | E13: 1. Pantau status perangkat pada menu Devices selama 60 detik | F13: Status perangkat konsisten ONLINE (Hijau) dengan latency_ms tercatat realistis | H13: NOT TESTED | I13: Critical | J13: REQ-DEV-06 | L13: [Tester] | M13: [Date]
A14: TC-DEV-010 | B14: Status Integrity | C14: Deteksi otomatis status OFFLINE saat komunikasi terputus | D14: Sensor dalam keadaan online | E14: 1. Putus koneksi kabel RS-485 2. Amati status perangkat pada menu Devices | F14: Status perangkat berubah menjadi OFFLINE (Merah) dalam waktu < 15 detik | H14: NOT TESTED | I14: Critical | J14: REQ-DEV-07 | L14: [Tester] | M14: [Date]
A15: TC-DEV-011 | B15: Hardware Resilience | C15: Penanganan serial port busy / resource lock | D15: Port serial /dev/ttyUSB0 sedang diakses oleh proses eksternal | E15: 1. Buka port menggunakan serial terminal lain 2. Jalankan polling datalogger | F15: Datalogger mencatat error 'serial port busy' secara elegan tanpa crash dan mencoba reconnect | H15: NOT TESTED | I15: High | J15: REQ-COMM-04 | L15: [Tester] | M15: [Date]
A16: TC-DEV-012 | B16: Hardware Resilience | C16: Auto-reconnect setelah converter USB-Serial dicabut dan dipasang kembali | D16: Polling Modbus RTU sedang berjalan normal | E16: 1. Cabut kabel USB converter dari host server 2. Tunggu 10 detik 3. Pasang kembali ke port USB yang sama | F16: Engine mendeteksi re-attach port serial dan secara otomatis memulihkan polling ke status ONLINE | H16: NOT TESTED | I16: Critical | J16: REQ-COMM-05 | L16: [Tester] | M16: [Date]
... A18: TC-DEV-014 | B18: Persistence | C18: Persistensi konfigurasi perangkat setelah reboot / restart service | D18: Perangkat AQMS-01 dan AQMS-02 terdaftar | E18: 1. Lakukan restart service datalogger 2. Buka menu Devices | F18: Seluruh daftar perangkat dan konfigurasi komunikasi termuat utuh dari database | H18: NOT TESTED | I18: Critical | J18: REQ-DEV-08 | L18: [Tester] | M18: [Date]

Sheet Parameter & Decoding
A1: DATALOGGER ANALYSIS APPLICATION — QA TEST CHECKLIST
A2: Module: Parameter & Decoding | Doc ID: DAA-QA-001 | Version: 1.0 | Status: Draft for QA Execution | Scope: Pengujian decoding register sensor, tipe data IEEE-754 Float32, endianness, kalibrasi, dan formula.
A4: Test Case ID | B4: Test Category | C4: Test Scenario | D4: Preconditions | E4: Test Steps | F4: Expected Result | G4: Actual Result | H4: Status | I4: Severity | J4: Evidence Reference | K4: Defect ID | L4: Tester | M4: Test Date | N4: Remarks
A5: TC-PAR-001 | B5: Parameter Setup | C5: Penambahan parameter baru pada perangkat terdaftar | D5: Perangkat AQMS-02 telah aktif | E5: 1. Klik 'Add Parameter' pada detail perangkat AQMS-02 2. Daftarkan kode 'co', nama 'Karbon Monoksida', unit 'ug/m3' 3. Simpan | F5: Parameter terdaftar dan langsung masuk ke daftar polling perangkat | H5: NOT TESTED | I5: Critical | J5: REQ-PAR-01 | L5: [Tester] | M5: [Date]
A6: TC-PAR-002 | B6: Parameter Setup | C6: Pengeditan batas ambang warning dan critical parameter | D6: Parameter PM 2.5 telah terdaftar | E6: 1. Ubah warning_low=1, warning_high=150, critical_high=250 2. Simpan | F6: Batas ambang baru tersimpan dan mesin evaluasi alarm menggunakan batas baru | H6: NOT TESTED | I6: High | J6: REQ-PAR-02 | L6: [Tester] | M6: [Date]
A7: TC-PAR-003 | B7: Register Config | C7: Validasi register address dan register count | D7: Modal konfigurasi parameter | E7: 1. Masukkan register address negatif atau > 65535 2. Atur register count di luar 1 atau 2 untuk Float32 | F7: Form memvalidasi dan membatasi masukan register sesuai standar spesifikasi Modbus | H7: NOT TESTED | I7: Medium | J7: REQ-PAR-03 | L7: [Tester] | M7: [Date]
A8: TC-PAR-004 | B8: Data Decoding | C8: Decoding Float32 IEEE-754 dengan Word Order CDAB (Mid-Little Endian) | D8: Sensor gas menggunakan format Float32 byte swap CDAB | E8: 1. Kirim raw hex '00 00 42 80' (nilai desimal 64.0) 2. Periksa hasil decoding | F8: Aplikasi mengonversi byte register menjadi angka desimal tepat 64.00 | H8: NOT TESTED | I8: Critical | J8: REQ-DEC-01 | L8: [Tester] | M8: [Date]
A9: TC-PAR-005 | B9: Data Decoding | C9: Decoding Float32 IEEE-754 dengan Byte Order ABCD (Big Endian) | D9: Sensor meteorologi menggunakan format ABCD | E9: 1. Kirim raw hex '42 80 00 00' 2. Periksa hasil decoding | F9: Aplikasi mengonversi menjadi angka desimal tepat 64.00 | H9: NOT TESTED | I9: Critical | J9: REQ-DEC-02 | L9: [Tester] | M9: [Date]
A10: TC-PAR-006 | B10: Data Decoding | C10: Decoding integer INT16 Signed dan UINT16 Unsigned | D10: Sensor mengirimkan data suhu dalam 1 register bertipe INT16 | E10: 1. Kirim raw register 0xFF9C (-100 desimal) 2. Terapkan scale 0.1 | F10: Nilai terdekode dengan benar menjadi -10.0 °C | H10: NOT TESTED | I10: High | J10: REQ-DEC-03 | L10: [Tester] | M10: [Date]
A11: TC-PAR-007 | B11: Data Scaling | C11: Penerapan faktor skala (Scale Factor) pada nilai register | D11: Register membaca nilai mentah integer 2525 | E11: 1. Atur scale_factor = 0.01 pada parameter Temperature 2. Evaluasi hasil | F11: Nilai yang dihasilkan tepat 25.25 °C | H11: NOT TESTED | I11: High | J11: REQ-DEC-04 | L11: [Tester] | M11: [Date]
A12: TC-PAR-008 | B12: Data Calibration | C12: Penerapan nilai Offset kalibrasi matematika | D12: Sensor memiliki deviasi baseline +1.5 | E12: 1. Atur offset = -1.5 pada konfigurasi parameter 2. Kirim nilai mentah 10.0 | F12: Nilai terproses akhir yang tersimpan adalah 8.5 | H12: NOT TESTED | I12: High | J12: REQ-DEC-05 | L12: [Tester] | M12: [Date]
A13: TC-PAR-009 | B13: Data Formula | C13: Penerapan formula kustom (Formula Evaluation Engine) | D13: Parameter memerlukan konversi non-linear: '(value * 1.05) + 2.0' | E13: 1. Aktifkan formula pada parameter 2. Masukkan ekspresi formula matematika 3. Simulasikan input nilai 100 | F13: Hasil evaluasi formula menghasilkan nilai tepat 107.0 | H13: NOT TESTED | I13: Medium | J13: REQ-DEC-06 | L13: [Tester] | M13: [Date]
A14: TC-PAR-010 | B14: Engineering Units | C14: Verifikasi unit pengukuran resmi sesuai standar lingkungan | D14: Tabel parameter stasiun | E14: 1. Periksa unit untuk PM2.5, PM10, SO2, NO2, CO, O3, HC, Temp, Hum, Press, Wind | F14: Seluruh parameter memiliki label unit resmi (ug/m3, C, %, hPa, m/s, deg) | H14: NOT TESTED | I14: Medium | J14: REQ-PAR-04 | L14: [Tester] | M14: [Date]
A15: TC-PAR-011 | B15: Equivalence Check | C15: Komparasi hasil decoding dengan nilai referensi simulator | D15: Modbus Slave Simulator mengirim paket data terkalibrasi | E15: 1. Bandingkan 14 nilai parameter di simulator dengan nilai di menu Live Telemetry | F15: Delta perbedaan antara nilai referensi dan nilai aplikasi adalah 0.00 (100% presisi) | H15: NOT TESTED | I15: Critical | J15: REQ-DEC-07 | L15: [Tester] | M15: [Date]
A16: TC-PAR-012 | B16: Data Sanitation | C16: Penolakan nilai matematika invalid (NaN dan Infinity) | D16: Kondisi pembagian dengan nol atau ekspresi formula error | E16: 1. Simulasikan formula 'value / 0' 2. Amati penanganan nilai | F16: Sistem menandai kualitas sebagai BAD dan tidak menyimpan nilai NaN ke database | H16: NOT TESTED | I16: Critical | J16: REQ-DEC-08 | L16: [Tester] | M16: [Date]
... A18: TC-PAR-014 | B18: Dynamic Reload | C18: Penerapan dinamis perubahan konfigurasi parameter | D18: Engine sedang melakukan polling aktif | E18: 1. Ubah nama parameter dan batas ambang via UI 2. Pantau siklus polling berikutnya | F18: Perubahan langsung diterapkan pada siklus pembacaan berikutnya tanpa restart daemon | H18: NOT TESTED | I18: High | J18: REQ-PAR-06 | L18: [Tester] | M18: [Date]

Sheet Polling Plan & Batch Read
A1: DATALOGGER ANALYSIS APPLICATION — QA TEST CHECKLIST
A2: Module: Polling Plan & Batch Read | Doc ID: DAA-QA-001 | Version: 1.0 | Status: Draft for QA Execution | Scope: Pengujian optimasi request Modbus Batch Read, register grouping, circuit breaker, dan fallback.
A4: Test Case ID | B4: Test Category | C4: Test Scenario | D4: Preconditions | E4: Test Steps | F4: Expected Result | G4: Actual Result | H4: Status | I4: Severity | J4: Evidence Reference | K4: Defect ID | L4: Tester | M4: Test Date | N4: Remarks
A5: TC-POLL-001 | B5: Batch Configuration | C5: Verifikasi Batch Read default OFF untuk perangkat baru | D5: Perangkat baru didaftarkan | E5: 1. Periksa field batch_read_enabled pada konfigurasi perangkat | F5: Nilai default adalah false (OFF) untuk mencegah tabrakan pada instrumen sensitif | H5: NOT TESTED | I5: High | J5: REQ-BATCH-01 | L5: [Tester] | M5: [Date]
A6: TC-POLL-002 | B6: Batch Configuration | C6: Konfigurasi perangkat lama tidak berubah secara tidak sengaja | D6: Database berisi konfigurasi perangkat eksisting | E6: 1. Jalankan migrasi 2. Periksa konfigurasi perangkat eksisting | F6: Nilai mode baca single read pada perangkat lama tetap terjaga 100% | H6: NOT TESTED | I6: High | J6: REQ-BATCH-02 | L6: [Tester] | M6: [Date]
A7: TC-POLL-003 | B7: Batch Planner | C7: Deteksi dan komputasi otomatis pada Mode AUTO | D7: batch_mode diset ke AUTO | E7: 1. Buat 4 parameter pada register berurutan (address 10, 12, 14, 16) 2. Evaluasi Polling Plan | F7: Engine otomatis menggabungkan ke dalam 1 request batch read (start=10, count=8) | H7: NOT TESTED | I7: High | J7: REQ-BATCH-03 | L7: [Tester] | M7: [Date]
A8: TC-POLL-004 | B8: Batch Planner | C8: Mode SINGLE tetap mempertahankan request per-register | D8: batch_mode diset ke SINGLE | E8: 1. Daftarkan beberapa parameter 2. Pantau frame komunikasi di Live Comm | F8: Setiap parameter dibaca menggunakan request Modbus terpisah secara sekuensial | H8: NOT TESTED | I8: High | J8: REQ-BATCH-04 | L8: [Tester] | M8: [Date]
A9: TC-POLL-005 | B9: Batch Planner | C9: Pengelompokan register berurutan ke dalam 1 request Modbus | D9: Parameter PM10 (reg 22) dan O3 (reg 38) | E9: 1. Aktifkan batch read 2. Amati frame request TX | F9: Engine mematuhi aturan pengelompokan holding register Function Code 03 | H9: NOT TESTED | I9: Critical | J9: REQ-BATCH-05 | L9: [Tester] | M9: [Date]
A10: TC-POLL-006 | B10: Batch Constraints | C10: Kepatuhan batas maximum register gap (max_register_gap) | D10: max_register_gap dikonfigurasi = 5 register | E10: 1. Parameter A pada reg 10 (count 2), Parameter B pada reg 20 (gap = 8) 2. Evaluasi plan | F10: Engine memisahkan menjadi 2 batch berbeda karena gap (8) melebihi batas (5) | H10: NOT TESTED | I10: High | J10: REQ-BATCH-06 | L10: [Tester] | M10: [Date]
A11: TC-POLL-007 | B11: Batch Constraints | C11: Kepatuhan batas maximum batch registers (max_batch_registers) | D11: max_batch_registers dikonfigurasi = 20 register | E11: 1. Daftarkan 15 parameter Float32 (total 30 register berurutan) 2. Evaluasi plan | F11: Engine memecah request menjadi 2 batch (batch 1 = 20 register, batch 2 = 10 register) | H11: NOT TESTED | I11: High | J11: REQ-BATCH-07 | L11: [Tester] | M11: [Date]
A12: TC-POLL-008 | B12: Batch Isolation | C12: Isolasi Slave ID yang berbeda dalam batch terpisah | D12: Parameter 1 pada Slave ID 1, Parameter 2 pada Slave ID 2 | E12: 1. Aktifkan batch read | F12: Engine tidak pernah menggabungkan parameter dengan Slave ID berbeda ke dalam 1 request | H12: NOT TESTED | I12: Critical | J12: REQ-BATCH-08 | L12: [Tester] | M12: [Date]
A13: TC-POLL-009 | B13: Batch Isolation | C13: Isolasi Function Code berbeda (Holding 03 vs Input 04) | D13: Parameter 1 pada Holding Register, Parameter 2 pada Input Register | E13: 1. Aktifkan batch read | F13: Engine memisahkan request Function 03 dan Function 04 secara ketat | H13: NOT TESTED | I13: Critical | J13: REQ-BATCH-09 | L13: [Tester] | M13: [Date]
A14: TC-POLL-010 | B14: PDU Calculation | C14: Presisi perhitungan PDU Start Address dan Register Count | D14: Parameter mulai dari address 100 dengan panjang 2 register | E14: 1. Periksa byte PDU Modbus pada frame TX | F14: Byte address dan byte count pada frame heksadesimal cocok 100% dengan PDU Modbus standard | H14: NOT TESTED | I14: High | J14: REQ-BATCH-10 | L14: [Tester] | M14: [Date]
A15: TC-POLL-011 | B15: Equivalence Check | C15: Kesetaraan hasil baca Batch Read vs Single Read | D15: Kondisi sensor menghasilkan data konstan | E15: 1. Baca nilai 14 parameter menggunakan Single Read 2. Beralih ke Batch Read dan baca nilai 14 parameter 3. Bandingkan | F15: Nilai yang dihasilkan identik 100% tanpa distorsi posisi byte/word order | H15: NOT TESTED | I15: Critical | J15: REQ-BATCH-11 | L15: [Tester] | M15: [Date]
A16: TC-POLL-012 | B16: Fault Tolerance | C16: Fallback otomatis ke Single Read saat Batch Request gagal | D16: Perangkat menolak membaca rentang register besar (menghasilkan Modbus Exception 02) | E16: 1. Kirim request batch yang gagal 2. Amati reaksi engine polling | F16: Engine otomatis fallback melakukan pembacaan single register sehingga parameter lain tetap terbaca | H16: NOT TESTED | I16: Critical | J16: REQ-BATCH-12 | L16: [Tester] | M16: [Date]
... A18: TC-POLL-014 | B18: UI Visualization | C18: Visualisasi Polling Plan Preview pada dashboard admin | D18: Login sebagai Admin/Superadmin | E18: 1. Buka modal Polling Plan Preview pada konfigurasi perangkat | F18: Tampilan visual menampilkan blok batch, estimasi reduksi cycle time, dan daftar register dengan akurat | H18: NOT TESTED | I18: Medium | J18: REQ-BATCH-14 | L18: [Tester] | M18: [Date]

Sheet Telemetry & Data Integrity
A1: DATALOGGER ANALYSIS APPLICATION — QA TEST CHECKLIST
A2: Module: Telemetry & Data Integrity | Doc ID: DAA-QA-001 | Version: 1.0 | Status: Draft for QA Execution | Scope: Pengujian aliran telemetri real-time, validasi timestamp, status mutu data, dan integritas penyimpanan.
A4: Test Case ID | B4: Test Category | C4: Test Scenario | D4: Preconditions | E4: Test Steps | F4: Expected Result | G4: Actual Result | H4: Status | I4: Severity | J4: Evidence Reference | K4: Defect ID | L4: Tester | M4: Test Date | N4: Remarks
A5: TC-TEL-001 | B5: Data Ingestion | C5: Aliran data telemetri baru diterima pada cadence 5 detik | D5: Stasiun dalam kondisi polling normal | E5: 1. Buka menu Live Telemetry 2. Amati indikator 'Last packet' dan denyut pulsa | F5: Data diperbarui setiap 5 detik secara teratur tanpa lonjakan jeda waktu | H5: NOT TESTED | I5: Critical | J5: REQ-TEL-01 | L5: [Tester] | M5: [Date]
A6: TC-TEL-002 | B6: Data Integrity | C6: Akurasi nilai telemetri terhadap sumber analyzer | D6: Analyzer terkalibrasi menampilkan nilai konsentrasi | E6: 1. Catat pembacaan pada layar fisik analyzer 2. Bandingkan dengan nilai di dashboard datalogger | F6: Nilai di datalogger presisi sesuai pembacaan analyzer dalam toleransi kalibrasi | H6: NOT TESTED | I6: Critical | J6: REQ-TEL-02 | L6: [Tester] | M6: [Date]
A7: TC-TEL-003 | B7: Timestamp & Timezone | C7: Validasi format timestamp ISO-8601 dan timezone lokal WIB | D7: Host server tersinkronisasi NTP | E7: 1. Periksa field timestamp pada tabel telemetry_readings 2. Verifikasi zona waktu pada UI | F7: Timestamp tercatat dalam format UTC di database dan terkonversi akurat ke WIB (UTC+7) di antarmuka | H7: NOT TESTED | I7: High | J7: REQ-TEL-03 | L7: [Tester] | M7: [Date]
A8: TC-TEL-004 | B8: Storage Integrity | C8: Penyimpanan data dengan foreign key device_id dan parameter_id yang valid | D8: Data telemetri masuk | E8: 1. Jalankan query database pada telemetry_readings 2. Periksa relasi ke tabel devices dan parameters | F8: Setiap baris tersimpan dengan relasi foreign key yang benar tanpa orphaned records | H8: NOT TESTED | I8: Critical | J8: REQ-TEL-04 | L8: [Tester] | M8: [Date]
A9: TC-TEL-005 | B9: Deduplication | C9: Uji idempotensi dan pencegahan duplikasi data telemetri | D9: Dua siklus polling dieksekusi | E9: 1. Periksa index unik (device_id, parameter_id, timestamp) 2. Coba simpan paket ganda | F9: Database menolak duplikasi data pada detik yang sama untuk parameter yang sama | H9: NOT TESTED | I9: High | J9: REQ-TEL-05 | L9: [Tester] | M9: [Date]
A10: TC-TEL-006 | B10: Quality Evaluation | C10: Penetapan status mutu GOOD pada kondisi normal | D10: Pembacaan sensor valid dan stabil | E10: 1. Buka menu Live Telemetry 2. Amati badge mutu | F10: Parameter menampilkan badge hijau 'GOOD' dengan keterangan 'CRC & Modbus valid' | H10: NOT TESTED | I10: High | J10: REQ-TEL-06 | L10: [Tester] | M10: [Date]
A11: TC-TEL-007 | B11: Quality Evaluation | C11: Penetapan status mutu UNCERTAIN pada kondisi peringatan | D11: Nilai mendekati ambang batas warning_high atau sensor mulai stuck | E11: 1. Kirim nilai di atas ambang warning 2. Amati badge mutu | F11: Status berubah menjadi kuning 'UNCERTAIN' dengan alasan 'OUT_OF_WARNING_RANGE' | H11: NOT TESTED | I11: High | J11: REQ-TEL-07 | L11: [Tester] | M11: [Date]
A12: TC-TEL-008 | B12: Quality Evaluation | C12: Penetapan status mutu BAD pada kondisi error fisik | D12: Sensor mengirimkan nilai negatif di luar batas fisik atau terjadi Modbus error | E12: 1. Simulasikan nilai out-of-range 2. Amati badge mutu | F12: Status berubah menjadi merah 'BAD' dan nilai tidak diikutsertakan dalam rata-rata baku mutu | H12: NOT TESTED | I12: Critical | J12: REQ-TEL-08 | L12: [Tester] | M12: [Date]
A13: TC-TEL-009 | B13: Stale Detection | C13: Deteksi dan penandaan status data STALE saat timeout | D13: Transmisi data dihentikan paksa | E13: 1. Hentikan transmisi sensor selama > 120 detik 2. Amati kartu Live Telemetry | F13: Status berubah menjadi 'STALE' (Timed Out) dan denyut pulsa hijau berhenti | H13: NOT TESTED | I13: High | J13: REQ-TEL-09 | L13: [Tester] | M13: [Date]
A14: TC-TEL-010 | B14: Channel Separation | C14: Isolasi data 14 parameter tanpa kontaminasi silang | D14: 14 parameter aktif secara simultan | E14: 1. Simulasikan perubahan nilai ekstrem pada PM2.5 2. Amati nilai parameter SO2, CO, dan Suhu | F14: Hanya nilai PM2.5 yang berubah, nilai parameter lain tetap independen tanpa kebocoran memori buffer | H14: NOT TESTED | I14: Critical | J14: REQ-TEL-10 | L14: [Tester] | M14: [Date]
A15: TC-TEL-011 | B15: Live Updates | C15: Pembaruan real-time pada UI tanpa me-refresh halaman browser | D15: Dashboard terbuka di layar | E15: 1. Amati tampilan angka sensor selama 30 detik tanpa menyentuh keyboard/mouse | F15: Angka sensor dan grafik trend otomatis ter-render ulang secara halus saat data baru tiba | H15: NOT TESTED | I15: High | J15: REQ-TEL-11 | L15: [Tester] | M15: [Date]
A16: TC-TEL-012 | B16: Buffer Recovery | C16: Penanganan reconnect jaringan tanpa kehilangan data (Local Buffering) | D16: Koneksi jaringan klien terputus selama 1 menit | E16: 1. Putus koneksi LAN klien 2. Sambungkan kembali 3. Buka grafik historis | F16: Data selama pemutusan tetap tersimpan utuh di MariaDB Edge dan langsung muncul saat refresh | H16: NOT TESTED | I16: High | J16: REQ-TEL-12 | L16: [Tester] | M16: [Date]

Sheet Aggregation & Rollup
A1: DATALOGGER ANALYSIS APPLICATION — QA TEST CHECKLIST
A2: Module: Aggregation & Rollup | Doc ID: DAA-QA-001 | Version: 1.0 | Status: Draft for QA Execution | Scope: Pengujian agregasi statistik berkala (1m, 5m, 1h, 1d), penanganan data kosong, dan integritas rollup.
A4: Test Case ID | B4: Test Category | C4: Test Scenario | D4: Preconditions | E4: Test Steps | F4: Expected Result | G4: Actual Result | H4: Status | I4: Severity | J4: Evidence Reference | K4: Defect ID | L4: Tester | M4: Test Date | N4: Remarks
A5: TC-AGGR-001 | B5: Rollup Execution | C5: Komputasi agregasi interval 1 menit (1-Minute Rollup) | D5: Data telemetri mentah tersedia selama minimal 2 menit | E5: 1. Tunggu pergantian menit 2. Periksa tabel telemetry_aggregations untuk interval '1m' | F5: Tersedia baris ringkasan dengan avg_value, min_value, max_value, dan sample_count tepat | H5: NOT TESTED | I5: Critical | J5: REQ-AGGR-01 | L5: [Tester] | M5: [Date]
A6: TC-AGGR-002 | B6: Rollup Execution | C6: Komputasi agregasi interval 5 menit (5-Minute Rollup) | D6: Data telemetri mentah tersedia selama 10 menit | E6: 1. Periksa tabel agregasi untuk interval '5m' | F6: Nilai rata-rata 5 menit terhitung akurat sesuai rumus matematika rata-rata terbobot | H6: NOT TESTED | I6: High | J6: REQ-AGGR-02 | L6: [Tester] | M6: [Date]
A7: TC-AGGR-003 | B7: Rollup Execution | C7: Komputasi agregasi interval 1 jam (Hourly Rollup) | D7: Data telemetri tersedia selama 2 jam | E7: 1. Periksa tabel agregasi untuk interval '1h' pada pergantian jam | F7: Agregasi 1 jam terkomputasi tepat pada batas jam (xx:00:00) dengan data completeness tercatat | H7: NOT TESTED | I7: Critical | J7: REQ-AGGR-03 | L7: [Tester] | M7: [Date]
A8: TC-AGGR-004 | B8: Rollup Execution | C8: Komputasi agregasi harian (Daily Rollup) | D8: Data telemetri tersedia selama 24 jam | E8: 1. Periksa tabel agregasi untuk interval '1d' pada pk 00:00:00 WIB | F8: Agregasi harian terhitung akurat untuk evaluasi baku mutu tahunan/bulanan | H8: NOT TESTED | I8: High | J8: REQ-AGGR-04 | L8: [Tester] | M8: [Date]
A9: TC-AGGR-005 | B9: Time Boundary | C9: Presisi boundary waktu window interval agregasi | D9: Data masuk pada detik 14:59:59 dan 15:00:00 | E9: 1. Periksa alokasi window kedua sampel data | F9: Sampel detik 59 masuk ke window jam 14, sampel detik 00 masuk ke window jam 15 secara presisi | H9: NOT TESTED | I9: High | J9: REQ-AGGR-05 | L9: [Tester] | M9: [Date]
A10: TC-AGGR-006 | B10: Quality Filter | C10: Pengecualian data berstatus BAD dari formula rata-rata agregasi | D10: Dataset uji berisi 8 data GOOD (nilai 50.0) dan 2 data BAD (nilai 9999.0) | E10: 1. Jalankan kalkulasi agregasi 2. Periksa avg_value yang dihasilkan | F10: Rata-rata terhitung tepat 50.0 (nilai BAD dieksklusi dari pembilang dan penyebut) | H10: NOT TESTED | I10: Critical | J10: REQ-AGGR-06 | L10: [Tester] | M10: [Date]
A11: TC-AGGR-007 | B11: Empty Period | C11: Penanganan periode waktu dengan data kosong (Missing Data Handling) | D11: Stasiun mati selama 3 jam | E11: 1. Periksa hasil query agregasi pada 3 jam tersebut | F11: Sistem tidak crash, baris agregasi mencatat NULL dengan valid_count=0 secara elegan | H11: NOT TESTED | I11: High | J11: REQ-AGGR-07 | L11: [Tester] | M11: [Date]
A12: TC-AGGR-008 | B12: Equivalence Check | C12: Verifikasi konsistensi rollup terhadap query raw aggregation manual | D12: Data mentah tersimpan di database | E12: 1. Jalankan query SQL manual 'SELECT AVG(value) FROM telemetry_readings WHERE...' 2. Bandingkan dengan avg_value tabel agregasi | F12: Nilai kalkulasi engine rollup identik dengan query manual SQL tanpa deviasi numerik | H12: NOT TESTED | I12: Critical | J12: REQ-AGGR-08 | L12: [Tester] | M12: [Date]
A13: TC-AGGR-009 | B13: Idempotency | C13: Pencegahan duplikasi baris saat eksekusi rollup berulang (Idempotent Rollup) | D13: Agregasi jam 10 telah dihitung | E13: 1. Picu kalkulasi ulang (recalculate) agregasi jam 10 via command/endpoint | F13: Baris lama di-update (UPSERT) tanpa menghasilkan baris ganda di database | H13: NOT TESTED | I13: High | J13: REQ-AGGR-09 | L13: [Tester] | M13: [Date]
A14: TC-AGGR-010 | B14: Storage Schema | C14: Pemisahan penyimpanan data agregasi pada tabel khusus | D14: Database MariaDB aktif | E14: 1. Verifikasi skema tabel telemetry_aggregations terpisah dari telemetry_readings | F14: Tabel agregasi memiliki indeks terpisah untuk menjamin query historis tetap cepat | H14: NOT TESTED | I14: Medium | J14: REQ-AGGR-10 | L14: [Tester] | M14: [Date]

Sheet Dashboard & UI
A1: DATALOGGER ANALYSIS APPLICATION — QA TEST CHECKLIST
A2: Module: Dashboard & UI | Doc ID: DAA-QA-001 | Version: 1.0 | Status: Draft for QA Execution | Scope: Pengujian tampilan SCADA Operator Console, rendering grafik, tema Dark/Light, bahasa, dan responsivitas.
A4: Test Case ID | B4: Test Category | C4: Test Scenario | D4: Preconditions | E4: Test Steps | F4: Expected Result | G4: Actual Result | H4: Status | I4: Severity | J4: Evidence Reference | K4: Defect ID | L4: Tester | M4: Test Date | N4: Remarks
A5: TC-UI-001 | B5: SCADA Console | C5: Pemuatan lengkap Operator Command Center setelah login | D5: Login sebagai Operator | E5: 1. Akses /#/monitoring/operator 2. Amati waktu render seluruh kartu dan grafik | F5: Seluruh 6 zona dashboard SCADA ter-render sempurna dalam waktu < 2 detik | H5: NOT TESTED | I5: Critical | J5: REQ-UI-02 | L5: [Tester] | M5: [Date]
A6: TC-UI-002 | B6: Header Elements | C6: Verifikasi Header Terpadu (Logo, Nama Customer, Jam Digital, Logo Maker) | D6: Dashboard terbuka | E6: 1. Periksa logo customer di kiri 2. Periksa jam digital pusat (Hari, Tanggal, Jam:Menit:Detik) 3. Periksa logo maker di kanan | F6: Komponen header tersusun seimbang, jam digital berdetik sinkron setiap detik | H6: NOT TESTED | I6: High | J6: REQ-UI-03 | L6: [Tester] | M6: [Date]
A7: TC-UI-003 | B7: Status Indicator | C7: Indikator status stasiun (ONLINE hijau / OFFLINE merah) | D7: Stasiun dalam kondisi operasional | E7: 1. Periksa badge status di samping nama stasiun | F7: Status menampilkan 'SCADA' dengan dot hijau pulsatif saat stasiun online | H7: NOT TESTED | I7: High | J7: REQ-UI-04 | L7: [Tester] | M7: [Date]
A8: TC-UI-004 | B8: Sensor Cards | C8: Tampilan 14 kartu parameter sensor dengan nilai besar dan unit resmi | D8: 14 parameter aktif | E8: 1. Periksa kartu PM2.5, PM10, O3, SO2, NO2, CO, HC, Temp, Hum, Press, Wind | F8: Setiap kartu menampilkan nama parameter, angka besar desimal presisi, satuan, dan badge GAS/MET | H8: NOT TESTED | I8: Critical | J8: REQ-UI-05 | L8: [Tester] | M8: [Date]
A9: TC-UI-005 | B9: Sensor Cards | C9: Tampilan sparkline mini dan trend arah panah | D9: Tersedia data historis beberapa siklus | E9: 1. Amati grafik mini sparkline pada setiap kartu sensor | F9: Sparkline menampilkan pola kurva 10 titik terakhir secara dinamis | H9: NOT TESTED | I9: Medium | J9: REQ-UI-06 | L9: [Tester] | M9: [Date]
A10: TC-UI-006 | B10: Live Cadence | C10: Pembaruan angka sensor secara dinamis saat data baru masuk | D10: Data masuk per 5 detik | E10: 1. Amati kartu saat nilai sensor berubah di simulator | F10: Nilai angka pada kartu langsung diperbarui seketika tanpa flicker visual | H10: NOT TESTED | I10: Critical | J10: REQ-UI-07 | L10: [Tester] | M10: [Date]
A11: TC-UI-007 | B11: ISPU Strip | C11: Tampilan strip status cepat ISPU stasiun | D11: Data 24 jam tersedia | E11: 1. Periksa pita ISPU di atas grafik trend | F11: Menampilkan angka indeks (misal: 93), Kategori (SEDANG), Dominant Pollutant (PM25), dan status VALID (96%) | H11: NOT TESTED | I11: Critical | J11: REQ-UI-08 | L11: [Tester] | M11: [Date]
A12: TC-UI-008 | B12: Trend Chart | C12: Rendering grafik Trend Analysis multi-parameter bawah (14 kurva) | D12: Dashboard terbuka | E12: 1. Amati grafik kurva bawah | F12: 14 garis warna-warni ter-render mulus dengan sumbu waktu X dan sumbu nilai Y proporsional | H12: NOT TESTED | I12: Critical | J12: REQ-UI-09 | L12: [Tester] | M12: [Date]
A13: TC-UI-009 | B13: Trend Chart | C13: Penggantian rentang waktu grafik trend (1m, 5m, 15m, 1h, 6h) | D13: Grafik sedang menampilkan rentang 15m | E13: 1. Klik tombol '1m' 2. Klik tombol '1h' 3. Klik tombol '6h' | F13: Grafik memperbarui sumbu waktu dan merender data sesuai rentang yang dipilih | H13: NOT TESTED | I13: High | J13: REQ-UI-10 | L13: [Tester] | M13: [Date]
A14: TC-UI-010 | B14: Trend Chart | C14: Isolasi parameter via toggle legenda pada grafik trend | D14: Grafik menampilkan seluruh 14 parameter | E14: 1. Klik label parameter 'PM2.5' pada legenda untuk menyembunyikan 2. Klik kembali untuk memunculkan | F14: Garis kurva PM2.5 hilang dan muncul kembali secara interaktif | H14: NOT TESTED | I14: Medium | J14: REQ-UI-11 | L14: [Tester] | M14: [Date]
A15: TC-UI-011 | B15: Toolbar Control | C15: Fungsi tombol Sidebar Auto-Hide / Pin | D15: Sidebar sedang tampil | E15: 1. Klik tombol Auto-Hide pada toolbar atau header 2. Arahkan kursor menjauh dari sidebar | F15: Sidebar otomatis bergeser menyempit/hilang dan muncul kembali saat kursor diarahkan ke tepi kiri | H15: NOT TESTED | I15: High | J15: REQ-UI-12 | L15: [Tester] | M15: [Date]
A16: TC-UI-012 | B16: Toolbar Control | C16: Fungsi tombol Fullscreen SCADA mode | D16: Layar browser dalam mode jendela normal | E16: 1. Klik tombol Fullscreen pada toolbar SCADA 2. Tekan tombol ESC pada keyboard | F16: Aplikasi masuk ke mode layar penuh tanpa border browser dan keluar kembali secara normal | H16: NOT TESTED | I16: Medium | J16: REQ-UI-13 | L16: [Tester] | M16: [Date]
... A20: TC-UI-016 | B20: Console Health | C20: Ketiadaan error JavaScript yang tidak tertangani di browser console | D20: Buka Developer Tools Console (F12) | E20: 1. Jelajahi menu Operator Console, Devices, Telemetry, ISPU, Reports selama 5 menit | F20: Console bersih dari unhandled exception atau red error messages | H20: NOT TESTED | I20: Critical | J20: REQ-UI-17 | L20: [Tester] | M20: [Date]

Sheet Historical Data & Export
A1: DATALOGGER ANALYSIS APPLICATION — QA TEST CHECKLIST
A2: Module: Historical Data & Export | Doc ID: DAA-QA-001 | Version: 1.0 | Status: Draft for QA Execution | Scope: Pengujian penelusuran data historis, grafik multi-parameter, dan ekspor laporan PDF/CSV/HTML.
A4: Test Case ID | B4: Test Category | C4: Test Scenario | D4: Preconditions | E4: Test Steps | F4: Expected Result | G4: Actual Result | H4: Status | I4: Severity | J4: Evidence Reference | K4: Defect ID | L4: Tester | M4: Test Date | N4: Remarks
A5: TC-HIST-001 | B5: Historical Query | C5: Penelusuran data historis berdasarkan perangkat dan parameter | D5: Menu /#/monitoring/analysis terbuka | E5: 1. Pilih Device 'AQMS-02' 2. Pilih Parameter 'pm2.5' 3. Klik Refresh | F5: Tabel dan grafik menampilkan riwayat pembacaan khusus PM2.5 pada perangkat AQMS-02 | H5: NOT TESTED | I5: Critical | J5: REQ-HIST-01 | L5: [Tester] | M5: [Date]
A6: TC-HIST-002 | B6: Historical Filter | C6: Penerapan filter rentang waktu preset dan custom date-time | D6: Tersedia data beberapa hari | E6: 1. Pilih preset 'Last 24h' 2. Pilih mode 'Custom' dan masukkan start time serta end time spesifik | F6: Data yang disajikan tepat berada di dalam batas waktu yang ditentukan tanpa pergeseran zona waktu | H6: NOT TESTED | I6: High | J6: REQ-HIST-02 | L6: [Tester] | M6: [Date]
A7: TC-HIST-003 | B7: Scale Modes | C7: Visualisasi kurva pada mode Normalized Scale (0 - 100%) | D7: 14 parameter terpilih bersamaan | E7: 1. Klik tombol 'Normalized Scale (0-100%)' | F7: Kurva seluruh parameter tertata rapi dalam rentang 0-100% memudahkan analisis korelasi | H7: NOT TESTED | I7: High | J7: REQ-HIST-03 | L7: [Tester] | M7: [Date]
A8: TC-HIST-004 | B8: Scale Modes | C8: Visualisasi kurva pada mode Native Scale | D8: Parameter dengan satuan berbeda terpilih | E8: 1. Klik tombol 'Native Scale' | F8: Sumbu Y menampilkan nilai fisik murni sesuai rentang instrumen masing-masing | H8: NOT TESTED | I8: High | J8: REQ-HIST-04 | L8: [Tester] | M8: [Date]
A9: TC-HIST-005 | B9: Chart Interaction | C9: Interaksi tooltip grafis menampilkan timestamp dan seluruh nilai | D9: Grafik ter-render | E9: 1. Arahkan mouse ke titik puncak kurva | F9: Tooltip muncul menampilkan tanggal, jam, menit, detik, dan nilai seluruh parameter aktif pada titik tersebut | H9: NOT TESTED | I9: Medium | J9: REQ-HIST-05 | L9: [Tester] | M9: [Date]
A10: TC-HIST-006 | B10: Reporting Module | C10: Pemuatan modul pelaporan operasional (Reports View) | D10: Akses /#/monitoring/reports | E10: 1. Buka halaman Reports 2. Pilih tipe laporan 'Comprehensive Operational' 3. Pilih rentang 'Last 24 Hours' | F10: Halaman memuat ringkasan eksekutif, tabel ketersediaan, dan statistik parameter | H10: NOT TESTED | I10: Critical | J10: REQ-REP-01 | L10: [Tester] | M10: [Date]
A11: TC-HIST-007 | B11: Report Export | C11: Ekspor laporan ke format cetak PDF (Print / Save PDF) | D11: Laporan operasional telah ter-generate | E11: 1. Klik tombol 'Print / Save PDF' 2. Amati jendela dialog cetak browser | F11: Laporan terformat rapi untuk ukuran kertas A4 portrait lengkap dengan kop dan penomoran halaman | H11: NOT TESTED | I11: High | J11: REQ-REP-02 | L11: [Tester] | M11: [Date]
A12: TC-HIST-008 | B12: Data Export | C12: Ekspor dataset ke berkas spreadsheet CSV (CSV Export) | D12: Data historis tersedia | E12: 1. Klik tombol 'CSV Export' 2. Simpan berkas .csv 3. Buka di Microsoft Excel | F12: Berkas CSV terunduh sempurna, karakter encoding UTF-8 terbaca rapi, pemisah koma teratur | H12: NOT TESTED | I12: Critical | J12: REQ-EXP-01 | L12: [Tester] | M12: [Date]
A13: TC-HIST-009 | B13: Data Export | C13: Ekspor berkas HTML mandiri (Download HTML) | D13: Data laporan tersedia | E13: 1. Klik tombol 'Download HTML' 2. Buka berkas .html secara offline tanpa koneksi internet | F13: Halaman laporan terbuka mandiri dengan styling utuh tanpa ketergantungan server eksternal | H13: NOT TESTED | I13: High | J13: REQ-EXP-02 | L13: [Tester] | M13: [Date]
A14: TC-HIST-010 | B14: Column Integrity | C14: Verifikasi susunan kolom pada berkas hasil ekspor | D14: File CSV hasil ekspor dibuka | E14: 1. Periksa header kolom | F14: Header memuat Timestamp, Device Code, Parameter Name, Value, Unit, Quality Status secara konsisten | H14: NOT TESTED | I14: High | J14: REQ-EXP-03 | L14: [Tester] | M14: [Date]
A15: TC-HIST-011 | B15: Empty Handling | C15: Penanganan ekspor pada periode tanpa data | D15: Pilih rentang tanggal di masa depan yang belum memiliki data | E15: 1. Klik 'CSV Export' | F15: Sistem menampilkan notifikasi informatif bahwa tidak ada data pada periode tersebut tanpa error 500 | H15: NOT TESTED | I15: Medium | J15: REQ-EXP-04 | L15: [Tester] | M15: [Date]
A16: TC-HIST-012 | B16: Performance | C16: Penanganan ekspor dataset besar (> 50.000 baris) | D16: Rentang pencarian 30 hari data | E16: 1. Jalankan ekspor dataset 30 hari 2. Amati waktu eksekusi | F16: Backend melakukan streaming data secara efisien tanpa kehabisan memori (heap out of memory) | H16: NOT TESTED | I16: High | J16: REQ-EXP-05 | L16: [Tester] | M16: [Date]

Sheet Alarm, Logs & Audit Trail
A1: DATALOGGER ANALYSIS APPLICATION — QA TEST CHECKLIST
A2: Module: Alarm, Logs & Audit Trail | Doc ID: DAA-QA-001 | Version: 1.0 | Status: Draft for QA Execution | Scope: Pengujian pemicu alarm batas ambang, sensor macet, timeout, riwayat alarm, dan audit trail.
A4: Test Case ID | B4: Test Category | C4: Test Scenario | D4: Preconditions | E4: Test Steps | F4: Expected Result | G4: Actual Result | H4: Status | I4: Severity | J4: Evidence Reference | K4: Defect ID | L4: Tester | M4: Test Date | N4: Remarks
A5: TC-ALM-001 | B5: Alarm Trigger | C5: Pemicu alarm batas ambang atas (Threshold Warning / Critical High) | D5: Parameter PM10 memiliki warning_high = 150 ug/m3 | E5: 1. Kirim nilai konsentrasi PM10 = 180 ug/m3 2. Amati menu Active Incidents | F5: Alarm THRESHOLD_WARNING_HIGH muncul seketika dengan status ACTIVE dan warna kuning/merah | H5: NOT TESTED | I5: Critical | J5: REQ-ALM-01 | L5: [Tester] | M5: [Date]
